INFO:werkzeug:[31m[1mWARNING: This is a development server. Do not use it in a production deployment. Use a production WSGI server instead.[0m
 * Running on http://127.0.0.1:5000
INFO:werkzeug:[33mPress CTRL+C to quit[0m
ERROR:common.app:Exception on /auth/register [POST]
Traceback (most recent call last):
  File "C:\Users\USER\Documents\Projects\hng\backend\stage-2\venv\Lib\site-packages\sqlalchemy\engine\base.py", line 146, in __init__
    self._dbapi_connection = engine.raw_connection()
                             ^^^^^^^^^^^^^^^^^^^^^^^
  File "C:\Users\USER\Documents\Projects\hng\backend\stage-2\venv\Lib\site-packages\sqlalchemy\engine\base.py", line 3300, in raw_connection
    return self.pool.connect()
           ^^^^^^^^^^^^^^^^^^^
  File "C:\Users\USER\Documents\Projects\hng\backend\stage-2\venv\Lib\site-packages\sqlalchemy\pool\base.py", line 449, in connect
    return _ConnectionFairy._checkout(self)
           ^^^^^^^^^^^^^^^^^^^^^^^^^^^^^^^^
  File "C:\Users\USER\Documents\Projects\hng\backend\stage-2\venv\Lib\site-packages\sqlalchemy\pool\base.py", line 1263, in _checkout
    fairy = _ConnectionRecord.checkout(pool)
            ^^^^^^^^^^^^^^^^^^^^^^^^^^^^^^^^
  File "C:\Users\USER\Documents\Projects\hng\backend\stage-2\venv\Lib\site-packages\sqlalchemy\pool\base.py", line 712, in checkout
    rec = pool._do_get()
          ^^^^^^^^^^^^^^
  File "C:\Users\USER\Documents\Projects\hng\backend\stage-2\venv\Lib\site-packages\sqlalchemy\pool\impl.py", line 179, in _do_get
    with util.safe_reraise():
  File "C:\Users\USER\Documents\Projects\hng\backend\stage-2\venv\Lib\site-packages\sqlalchemy\util\langhelpers.py", line 146, in __exit__
    raise exc_value.with_traceback(exc_tb)
  File "C:\Users\USER\Documents\Projects\hng\backend\stage-2\venv\Lib\site-packages\sqlalchemy\pool\impl.py", line 177, in _do_get
    return self._create_connection()
           ^^^^^^^^^^^^^^^^^^^^^^^^^
  File "C:\Users\USER\Documents\Projects\hng\backend\stage-2\venv\Lib\site-packages\sqlalchemy\pool\base.py", line 390, in _create_connection
    return _ConnectionRecord(self)
           ^^^^^^^^^^^^^^^^^^^^^^^
  File "C:\Users\USER\Documents\Projects\hng\backend\stage-2\venv\Lib\site-packages\sqlalchemy\pool\base.py", line 674, in __init__
    self.__connect()
  File "C:\Users\USER\Documents\Projects\hng\backend\stage-2\venv\Lib\site-packages\sqlalchemy\pool\base.py", line 900, in __connect
    with util.safe_reraise():
  File "C:\Users\USER\Documents\Projects\hng\backend\stage-2\venv\Lib\site-packages\sqlalchemy\util\langhelpers.py", line 146, in __exit__
    raise exc_value.with_traceback(exc_tb)
  File "C:\Users\USER\Documents\Projects\hng\backend\stage-2\venv\Lib\site-packages\sqlalchemy\pool\base.py", line 896, in __connect
    self.dbapi_connection = connection = pool._invoke_creator(self)
                                         ^^^^^^^^^^^^^^^^^^^^^^^^^^
  File "C:\Users\USER\Documents\Projects\hng\backend\stage-2\venv\Lib\site-packages\sqlalchemy\engine\create.py", line 643, in connect
    return dialect.connect(*cargs, **cparams)
           ^^^^^^^^^^^^^^^^^^^^^^^^^^^^^^^^^^
  File "C:\Users\USER\Documents\Projects\hng\backend\stage-2\venv\Lib\site-packages\sqlalchemy\engine\default.py", line 620, in connect
    return self.loaded_dbapi.connect(*cargs, **cparams)
           ^^^^^^^^^^^^^^^^^^^^^^^^^^^^^^^^^^^^^^^^^^^^
  File "C:\Users\USER\Documents\Projects\hng\backend\stage-2\venv\Lib\site-packages\psycopg2\__init__.py", line 122, in connect
    conn = _connect(dsn, connection_factory=connection_factory, **kwasync)
           ^^^^^^^^^^^^^^^^^^^^^^^^^^^^^^^^^^^^^^^^^^^^^^^^^^^^^^^^^^^^^^^
psycopg2.OperationalError: connection to server at "localhost" (::1), port 5432 failed: FATAL:  database "postgresql" does not exist


The above exception was the direct cause of the following exception:

Traceback (most recent call last):
  File "C:\Users\USER\Documents\Projects\hng\backend\stage-2\venv\Lib\site-packages\flask\app.py", line 1473, in wsgi_app
    response = self.full_dispatch_request()
               ^^^^^^^^^^^^^^^^^^^^^^^^^^^^
  File "C:\Users\USER\Documents\Projects\hng\backend\stage-2\venv\Lib\site-packages\flask\app.py", line 882, in full_dispatch_request
    rv = self.handle_user_exception(e)
         ^^^^^^^^^^^^^^^^^^^^^^^^^^^^^
  File "C:\Users\USER\Documents\Projects\hng\backend\stage-2\venv\Lib\site-packages\flask_cors\extension.py", line 178, in wrapped_function
    return cors_after_request(app.make_response(f(*args, **kwargs)))
                                                ^^^^^^^^^^^^^^^^^^
  File "C:\Users\USER\Documents\Projects\hng\backend\stage-2\venv\Lib\site-packages\flask\app.py", line 880, in full_dispatch_request
    rv = self.dispatch_request()
         ^^^^^^^^^^^^^^^^^^^^^^^
  File "C:\Users\USER\Documents\Projects\hng\backend\stage-2\venv\Lib\site-packages\flask\app.py", line 865, in dispatch_request
    return self.ensure_sync(self.view_functions[rule.endpoint])(**view_args)  # type: ignore[no-any-return]
           ^^^^^^^^^^^^^^^^^^^^^^^^^^^^^^^^^^^^^^^^^^^^^^^^^^^^^^^^^^^^^^^^^
  File "C:\Users\USER\Documents\Projects\hng\backend\stage-2\routes\auth_route.py", line 14, in registerMain
    return register(data)
           ^^^^^^^^^^^^^^
  File "C:\Users\USER\Documents\Projects\hng\backend\stage-2\modules\auth\auth_controller.py", line 30, in register
    db.session.commit()
  File "C:\Users\USER\Documents\Projects\hng\backend\stage-2\venv\Lib\site-packages\sqlalchemy\orm\scoping.py", line 597, in commit
    return self._proxied.commit()
           ^^^^^^^^^^^^^^^^^^^^^^
  File "C:\Users\USER\Documents\Projects\hng\backend\stage-2\venv\Lib\site-packages\sqlalchemy\orm\session.py", line 2017, in commit
    trans.commit(_to_root=True)
  File "<string>", line 2, in commit
  File "C:\Users\USER\Documents\Projects\hng\backend\stage-2\venv\Lib\site-packages\sqlalchemy\orm\state_changes.py", line 139, in _go
    ret_value = fn(self, *arg, **kw)
                ^^^^^^^^^^^^^^^^^^^^
  File "C:\Users\USER\Documents\Projects\hng\backend\stage-2\venv\Lib\site-packages\sqlalchemy\orm\session.py", line 1302, in commit
    self._prepare_impl()
  File "<string>", line 2, in _prepare_impl
  File "C:\Users\USER\Documents\Projects\hng\backend\stage-2\venv\Lib\site-packages\sqlalchemy\orm\state_changes.py", line 139, in _go
    ret_value = fn(self, *arg, **kw)
                ^^^^^^^^^^^^^^^^^^^^
  File "C:\Users\USER\Documents\Projects\hng\backend\stage-2\venv\Lib\site-packages\sqlalchemy\orm\session.py", line 1277, in _prepare_impl
    self.session.flush()
  File "C:\Users\USER\Documents\Projects\hng\backend\stage-2\venv\Lib\site-packages\sqlalchemy\orm\session.py", line 4341, in flush
    self._flush(objects)
  File "C:\Users\USER\Documents\Projects\hng\backend\stage-2\venv\Lib\site-packages\sqlalchemy\orm\session.py", line 4476, in _flush
    with util.safe_reraise():
  File "C:\Users\USER\Documents\Projects\hng\backend\stage-2\venv\Lib\site-packages\sqlalchemy\util\langhelpers.py", line 146, in __exit__
    raise exc_value.with_traceback(exc_tb)
  File "C:\Users\USER\Documents\Projects\hng\backend\stage-2\venv\Lib\site-packages\sqlalchemy\orm\session.py", line 4437, in _flush
    flush_context.execute()
  File "C:\Users\USER\Documents\Projects\hng\backend\stage-2\venv\Lib\site-packages\sqlalchemy\orm\unitofwork.py", line 466, in execute
    rec.execute(self)
  File "C:\Users\USER\Documents\Projects\hng\backend\stage-2\venv\Lib\site-packages\sqlalchemy\orm\unitofwork.py", line 642, in execute
    util.preloaded.orm_persistence.save_obj(
  File "C:\Users\USER\Documents\Projects\hng\backend\stage-2\venv\Lib\site-packages\sqlalchemy\orm\persistence.py", line 60, in save_obj
    for (
  File "C:\Users\USER\Documents\Projects\hng\backend\stage-2\venv\Lib\site-packages\sqlalchemy\orm\persistence.py", line 223, in _organize_states_for_save
    for state, dict_, mapper, connection in _connections_for_states(
  File "C:\Users\USER\Documents\Projects\hng\backend\stage-2\venv\Lib\site-packages\sqlalchemy\orm\persistence.py", line 1753, in _connections_for_states
    connection = uowtransaction.transaction.connection(base_mapper)
                 ^^^^^^^^^^^^^^^^^^^^^^^^^^^^^^^^^^^^^^^^^^^^^^^^^^
  File "<string>", line 2, in connection
  File "C:\Users\USER\Documents\Projects\hng\backend\stage-2\venv\Lib\site-packages\sqlalchemy\orm\state_changes.py", line 139, in _go
    ret_value = fn(self, *arg, **kw)
                ^^^^^^^^^^^^^^^^^^^^
  File "C:\Users\USER\Documents\Projects\hng\backend\stage-2\venv\Lib\site-packages\sqlalchemy\orm\session.py", line 1039, in connection
    return self._connection_for_bind(bind, execution_options)
           ^^^^^^^^^^^^^^^^^^^^^^^^^^^^^^^^^^^^^^^^^^^^^^^^^^
  File "<string>", line 2, in _connection_for_bind
  File "C:\Users\USER\Documents\Projects\hng\backend\stage-2\venv\Lib\site-packages\sqlalchemy\orm\state_changes.py", line 139, in _go
    ret_value = fn(self, *arg, **kw)
                ^^^^^^^^^^^^^^^^^^^^
  File "C:\Users\USER\Documents\Projects\hng\backend\stage-2\venv\Lib\site-packages\sqlalchemy\orm\session.py", line 1175, in _connection_for_bind
    conn = self._parent._connection_for_bind(
           ^^^^^^^^^^^^^^^^^^^^^^^^^^^^^^^^^^
  File "<string>", line 2, in _connection_for_bind
  File "C:\Users\USER\Documents\Projects\hng\backend\stage-2\venv\Lib\site-packages\sqlalchemy\orm\state_changes.py", line 139, in _go
    ret_value = fn(self, *arg, **kw)
                ^^^^^^^^^^^^^^^^^^^^
  File "C:\Users\USER\Documents\Projects\hng\backend\stage-2\venv\Lib\site-packages\sqlalchemy\orm\session.py", line 1189, in _connection_for_bind
    conn = bind.connect()
           ^^^^^^^^^^^^^^
  File "C:\Users\USER\Documents\Projects\hng\backend\stage-2\venv\Lib\site-packages\sqlalchemy\engine\base.py", line 3276, in connect
    return self._connection_cls(self)
           ^^^^^^^^^^^^^^^^^^^^^^^^^^
  File "C:\Users\USER\Documents\Projects\hng\backend\stage-2\venv\Lib\site-packages\sqlalchemy\engine\base.py", line 148, in __init__
    Connection._handle_dbapi_exception_noconnection(
  File "C:\Users\USER\Documents\Projects\hng\backend\stage-2\venv\Lib\site-packages\sqlalchemy\engine\base.py", line 2440, in _handle_dbapi_exception_noconnection
    raise sqlalchemy_exception.with_traceback(exc_info[2]) from e
  File "C:\Users\USER\Documents\Projects\hng\backend\stage-2\venv\Lib\site-packages\sqlalchemy\engine\base.py", line 146, in __init__
    self._dbapi_connection = engine.raw_connection()
                             ^^^^^^^^^^^^^^^^^^^^^^^
  File "C:\Users\USER\Documents\Projects\hng\backend\stage-2\venv\Lib\site-packages\sqlalchemy\engine\base.py", line 3300, in raw_connection
    return self.pool.connect()
           ^^^^^^^^^^^^^^^^^^^
  File "C:\Users\USER\Documents\Projects\hng\backend\stage-2\venv\Lib\site-packages\sqlalchemy\pool\base.py", line 449, in connect
    return _ConnectionFairy._checkout(self)
           ^^^^^^^^^^^^^^^^^^^^^^^^^^^^^^^^
  File "C:\Users\USER\Documents\Projects\hng\backend\stage-2\venv\Lib\site-packages\sqlalchemy\pool\base.py", line 1263, in _checkout
    fairy = _ConnectionRecord.checkout(pool)
            ^^^^^^^^^^^^^^^^^^^^^^^^^^^^^^^^
  File "C:\Users\USER\Documents\Projects\hng\backend\stage-2\venv\Lib\site-packages\sqlalchemy\pool\base.py", line 712, in checkout
    rec = pool._do_get()
          ^^^^^^^^^^^^^^
  File "C:\Users\USER\Documents\Projects\hng\backend\stage-2\venv\Lib\site-packages\sqlalchemy\pool\impl.py", line 179, in _do_get
    with util.safe_reraise():
  File "C:\Users\USER\Documents\Projects\hng\backend\stage-2\venv\Lib\site-packages\sqlalchemy\util\langhelpers.py", line 146, in __exit__
    raise exc_value.with_traceback(exc_tb)
  File "C:\Users\USER\Documents\Projects\hng\backend\stage-2\venv\Lib\site-packages\sqlalchemy\pool\impl.py", line 177, in _do_get
    return self._create_connection()
           ^^^^^^^^^^^^^^^^^^^^^^^^^
  File "C:\Users\USER\Documents\Projects\hng\backend\stage-2\venv\Lib\site-packages\sqlalchemy\pool\base.py", line 390, in _create_connection
    return _ConnectionRecord(self)
           ^^^^^^^^^^^^^^^^^^^^^^^
  File "C:\Users\USER\Documents\Projects\hng\backend\stage-2\venv\Lib\site-packages\sqlalchemy\pool\base.py", line 674, in __init__
    self.__connect()
  File "C:\Users\USER\Documents\Projects\hng\backend\stage-2\venv\Lib\site-packages\sqlalchemy\pool\base.py", line 900, in __connect
    with util.safe_reraise():
  File "C:\Users\USER\Documents\Projects\hng\backend\stage-2\venv\Lib\site-packages\sqlalchemy\util\langhelpers.py", line 146, in __exit__
    raise exc_value.with_traceback(exc_tb)
  File "C:\Users\USER\Documents\Projects\hng\backend\stage-2\venv\Lib\site-packages\sqlalchemy\pool\base.py", line 896, in __connect
    self.dbapi_connection = connection = pool._invoke_creator(self)
                                         ^^^^^^^^^^^^^^^^^^^^^^^^^^
  File "C:\Users\USER\Documents\Projects\hng\backend\stage-2\venv\Lib\site-packages\sqlalchemy\engine\create.py", line 643, in connect
    return dialect.connect(*cargs, **cparams)
           ^^^^^^^^^^^^^^^^^^^^^^^^^^^^^^^^^^
  File "C:\Users\USER\Documents\Projects\hng\backend\stage-2\venv\Lib\site-packages\sqlalchemy\engine\default.py", line 620, in connect
    return self.loaded_dbapi.connect(*cargs, **cparams)
           ^^^^^^^^^^^^^^^^^^^^^^^^^^^^^^^^^^^^^^^^^^^^
  File "C:\Users\USER\Documents\Projects\hng\backend\stage-2\venv\Lib\site-packages\psycopg2\__init__.py", line 122, in connect
    conn = _connect(dsn, connection_factory=connection_factory, **kwasync)
           ^^^^^^^^^^^^^^^^^^^^^^^^^^^^^^^^^^^^^^^^^^^^^^^^^^^^^^^^^^^^^^^
sqlalchemy.exc.OperationalError: (psycopg2.OperationalError) connection to server at "localhost" (::1), port 5432 failed: FATAL:  database "postgresql" does not exist

(Background on this error at: https://sqlalche.me/e/20/e3q8)
INFO:werkzeug:127.0.0.1 - - [09/Jul/2024 14:53:02] "[35m[1mPOST /auth/register HTTP/1.1[0m" 500 -
INFO:werkzeug:[31m[1mWARNING: This is a development server. Do not use it in a production deployment. Use a production WSGI server instead.[0m
 * Running on http://127.0.0.1:5000
INFO:werkzeug:[33mPress CTRL+C to quit[0m
ERROR:common.app:Exception on /auth/register [POST]
Traceback (most recent call last):
  File "C:\Users\USER\Documents\Projects\hng\backend\stage-2\venv\Lib\site-packages\sqlalchemy\engine\base.py", line 1967, in _exec_single_context
    self.dialect.do_execute(
  File "C:\Users\USER\Documents\Projects\hng\backend\stage-2\venv\Lib\site-packages\sqlalchemy\engine\default.py", line 924, in do_execute
    cursor.execute(statement, parameters)
psycopg2.errors.UndefinedTable: relation "user" does not exist
LINE 1: INSERT INTO "user" ("userId", "firstName", "lastName", email...
                    ^


The above exception was the direct cause of the following exception:

Traceback (most recent call last):
  File "C:\Users\USER\Documents\Projects\hng\backend\stage-2\venv\Lib\site-packages\flask\app.py", line 1473, in wsgi_app
    response = self.full_dispatch_request()
               ^^^^^^^^^^^^^^^^^^^^^^^^^^^^
  File "C:\Users\USER\Documents\Projects\hng\backend\stage-2\venv\Lib\site-packages\flask\app.py", line 882, in full_dispatch_request
    rv = self.handle_user_exception(e)
         ^^^^^^^^^^^^^^^^^^^^^^^^^^^^^
  File "C:\Users\USER\Documents\Projects\hng\backend\stage-2\venv\Lib\site-packages\flask_cors\extension.py", line 178, in wrapped_function
    return cors_after_request(app.make_response(f(*args, **kwargs)))
                                                ^^^^^^^^^^^^^^^^^^
  File "C:\Users\USER\Documents\Projects\hng\backend\stage-2\venv\Lib\site-packages\flask\app.py", line 880, in full_dispatch_request
    rv = self.dispatch_request()
         ^^^^^^^^^^^^^^^^^^^^^^^
  File "C:\Users\USER\Documents\Projects\hng\backend\stage-2\venv\Lib\site-packages\flask\app.py", line 865, in dispatch_request
    return self.ensure_sync(self.view_functions[rule.endpoint])(**view_args)  # type: ignore[no-any-return]
           ^^^^^^^^^^^^^^^^^^^^^^^^^^^^^^^^^^^^^^^^^^^^^^^^^^^^^^^^^^^^^^^^^
  File "C:\Users\USER\Documents\Projects\hng\backend\stage-2\routes\auth_route.py", line 14, in registerMain
    return register(data)
           ^^^^^^^^^^^^^^
  File "C:\Users\USER\Documents\Projects\hng\backend\stage-2\modules\auth\auth_controller.py", line 30, in register
    db.session.commit()
  File "C:\Users\USER\Documents\Projects\hng\backend\stage-2\venv\Lib\site-packages\sqlalchemy\orm\scoping.py", line 597, in commit
    return self._proxied.commit()
           ^^^^^^^^^^^^^^^^^^^^^^
  File "C:\Users\USER\Documents\Projects\hng\backend\stage-2\venv\Lib\site-packages\sqlalchemy\orm\session.py", line 2017, in commit
    trans.commit(_to_root=True)
  File "<string>", line 2, in commit
  File "C:\Users\USER\Documents\Projects\hng\backend\stage-2\venv\Lib\site-packages\sqlalchemy\orm\state_changes.py", line 139, in _go
    ret_value = fn(self, *arg, **kw)
                ^^^^^^^^^^^^^^^^^^^^
  File "C:\Users\USER\Documents\Projects\hng\backend\stage-2\venv\Lib\site-packages\sqlalchemy\orm\session.py", line 1302, in commit
    self._prepare_impl()
  File "<string>", line 2, in _prepare_impl
  File "C:\Users\USER\Documents\Projects\hng\backend\stage-2\venv\Lib\site-packages\sqlalchemy\orm\state_changes.py", line 139, in _go
    ret_value = fn(self, *arg, **kw)
                ^^^^^^^^^^^^^^^^^^^^
  File "C:\Users\USER\Documents\Projects\hng\backend\stage-2\venv\Lib\site-packages\sqlalchemy\orm\session.py", line 1277, in _prepare_impl
    self.session.flush()
  File "C:\Users\USER\Documents\Projects\hng\backend\stage-2\venv\Lib\site-packages\sqlalchemy\orm\session.py", line 4341, in flush
    self._flush(objects)
  File "C:\Users\USER\Documents\Projects\hng\backend\stage-2\venv\Lib\site-packages\sqlalchemy\orm\session.py", line 4476, in _flush
    with util.safe_reraise():
  File "C:\Users\USER\Documents\Projects\hng\backend\stage-2\venv\Lib\site-packages\sqlalchemy\util\langhelpers.py", line 146, in __exit__
    raise exc_value.with_traceback(exc_tb)
  File "C:\Users\USER\Documents\Projects\hng\backend\stage-2\venv\Lib\site-packages\sqlalchemy\orm\session.py", line 4437, in _flush
    flush_context.execute()
  File "C:\Users\USER\Documents\Projects\hng\backend\stage-2\venv\Lib\site-packages\sqlalchemy\orm\unitofwork.py", line 466, in execute
    rec.execute(self)
  File "C:\Users\USER\Documents\Projects\hng\backend\stage-2\venv\Lib\site-packages\sqlalchemy\orm\unitofwork.py", line 642, in execute
    util.preloaded.orm_persistence.save_obj(
  File "C:\Users\USER\Documents\Projects\hng\backend\stage-2\venv\Lib\site-packages\sqlalchemy\orm\persistence.py", line 93, in save_obj
    _emit_insert_statements(
  File "C:\Users\USER\Documents\Projects\hng\backend\stage-2\venv\Lib\site-packages\sqlalchemy\orm\persistence.py", line 1233, in _emit_insert_statements
    result = connection.execute(
             ^^^^^^^^^^^^^^^^^^^
  File "C:\Users\USER\Documents\Projects\hng\backend\stage-2\venv\Lib\site-packages\sqlalchemy\engine\base.py", line 1418, in execute
    return meth(
           ^^^^^
  File "C:\Users\USER\Documents\Projects\hng\backend\stage-2\venv\Lib\site-packages\sqlalchemy\sql\elements.py", line 515, in _execute_on_connection
    return connection._execute_clauseelement(
           ^^^^^^^^^^^^^^^^^^^^^^^^^^^^^^^^^^
  File "C:\Users\USER\Documents\Projects\hng\backend\stage-2\venv\Lib\site-packages\sqlalchemy\engine\base.py", line 1640, in _execute_clauseelement
    ret = self._execute_context(
          ^^^^^^^^^^^^^^^^^^^^^^
  File "C:\Users\USER\Documents\Projects\hng\backend\stage-2\venv\Lib\site-packages\sqlalchemy\engine\base.py", line 1846, in _execute_context
    return self._exec_single_context(
           ^^^^^^^^^^^^^^^^^^^^^^^^^^
  File "C:\Users\USER\Documents\Projects\hng\backend\stage-2\venv\Lib\site-packages\sqlalchemy\engine\base.py", line 1986, in _exec_single_context
    self._handle_dbapi_exception(
  File "C:\Users\USER\Documents\Projects\hng\backend\stage-2\venv\Lib\site-packages\sqlalchemy\engine\base.py", line 2353, in _handle_dbapi_exception
    raise sqlalchemy_exception.with_traceback(exc_info[2]) from e
  File "C:\Users\USER\Documents\Projects\hng\backend\stage-2\venv\Lib\site-packages\sqlalchemy\engine\base.py", line 1967, in _exec_single_context
    self.dialect.do_execute(
  File "C:\Users\USER\Documents\Projects\hng\backend\stage-2\venv\Lib\site-packages\sqlalchemy\engine\default.py", line 924, in do_execute
    cursor.execute(statement, parameters)
sqlalchemy.exc.ProgrammingError: (psycopg2.errors.UndefinedTable) relation "user" does not exist
LINE 1: INSERT INTO "user" ("userId", "firstName", "lastName", email...
                    ^

[SQL: INSERT INTO "user" ("userId", "firstName", "lastName", email, password, phone) VALUES (%(userId)s, %(firstName)s, %(lastName)s, %(email)s, %(password)s, %(phone)s)]
[parameters: {'userId': '23a5f5a8-cc33-4ec7-a242-aa74210f1b02', 'firstName': 'Emmanuel', 'lastName': 'Omoiys', 'email': 'emmanuelomoiya7@gmail.com', 'password': b'$2b$12$.q3bGmw7UYgp93oMMkO0BuImNje0k1AubJ1W6HV19zfFRYPBsvfIW', 'phone': '+2347043738436'}]
(Background on this error at: https://sqlalche.me/e/20/f405)
INFO:werkzeug:127.0.0.1 - - [09/Jul/2024 14:53:57] "[35m[1mPOST /auth/register HTTP/1.1[0m" 500 -
INFO:werkzeug:[31m[1mWARNING: This is a development server. Do not use it in a production deployment. Use a production WSGI server instead.[0m
 * Running on http://127.0.0.1:5000
INFO:werkzeug:[33mPress CTRL+C to quit[0m
ERROR:common.app:Exception on /auth/register [POST]
Traceback (most recent call last):
  File "C:\Users\USER\Documents\Projects\hng\backend\stage-2\venv\Lib\site-packages\sqlalchemy\engine\base.py", line 1967, in _exec_single_context
    self.dialect.do_execute(
  File "C:\Users\USER\Documents\Projects\hng\backend\stage-2\venv\Lib\site-packages\sqlalchemy\engine\default.py", line 924, in do_execute
    cursor.execute(statement, parameters)
psycopg2.errors.UndefinedTable: relation "user" does not exist
LINE 1: INSERT INTO "user" ("userId", "firstName", "lastName", email...
                    ^


The above exception was the direct cause of the following exception:

Traceback (most recent call last):
  File "C:\Users\USER\Documents\Projects\hng\backend\stage-2\venv\Lib\site-packages\flask\app.py", line 1473, in wsgi_app
    response = self.full_dispatch_request()
               ^^^^^^^^^^^^^^^^^^^^^^^^^^^^
  File "C:\Users\USER\Documents\Projects\hng\backend\stage-2\venv\Lib\site-packages\flask\app.py", line 882, in full_dispatch_request
    rv = self.handle_user_exception(e)
         ^^^^^^^^^^^^^^^^^^^^^^^^^^^^^
  File "C:\Users\USER\Documents\Projects\hng\backend\stage-2\venv\Lib\site-packages\flask_cors\extension.py", line 178, in wrapped_function
    return cors_after_request(app.make_response(f(*args, **kwargs)))
                                                ^^^^^^^^^^^^^^^^^^
  File "C:\Users\USER\Documents\Projects\hng\backend\stage-2\venv\Lib\site-packages\flask\app.py", line 880, in full_dispatch_request
    rv = self.dispatch_request()
         ^^^^^^^^^^^^^^^^^^^^^^^
  File "C:\Users\USER\Documents\Projects\hng\backend\stage-2\venv\Lib\site-packages\flask\app.py", line 865, in dispatch_request
    return self.ensure_sync(self.view_functions[rule.endpoint])(**view_args)  # type: ignore[no-any-return]
           ^^^^^^^^^^^^^^^^^^^^^^^^^^^^^^^^^^^^^^^^^^^^^^^^^^^^^^^^^^^^^^^^^
  File "C:\Users\USER\Documents\Projects\hng\backend\stage-2\routes\auth_route.py", line 14, in registerMain
    return register(data)
           ^^^^^^^^^^^^^^
  File "C:\Users\USER\Documents\Projects\hng\backend\stage-2\modules\auth\auth_controller.py", line 30, in register
    db.session.commit()
  File "C:\Users\USER\Documents\Projects\hng\backend\stage-2\venv\Lib\site-packages\sqlalchemy\orm\scoping.py", line 597, in commit
    return self._proxied.commit()
           ^^^^^^^^^^^^^^^^^^^^^^
  File "C:\Users\USER\Documents\Projects\hng\backend\stage-2\venv\Lib\site-packages\sqlalchemy\orm\session.py", line 2017, in commit
    trans.commit(_to_root=True)
  File "<string>", line 2, in commit
  File "C:\Users\USER\Documents\Projects\hng\backend\stage-2\venv\Lib\site-packages\sqlalchemy\orm\state_changes.py", line 139, in _go
    ret_value = fn(self, *arg, **kw)
                ^^^^^^^^^^^^^^^^^^^^
  File "C:\Users\USER\Documents\Projects\hng\backend\stage-2\venv\Lib\site-packages\sqlalchemy\orm\session.py", line 1302, in commit
    self._prepare_impl()
  File "<string>", line 2, in _prepare_impl
  File "C:\Users\USER\Documents\Projects\hng\backend\stage-2\venv\Lib\site-packages\sqlalchemy\orm\state_changes.py", line 139, in _go
    ret_value = fn(self, *arg, **kw)
                ^^^^^^^^^^^^^^^^^^^^
  File "C:\Users\USER\Documents\Projects\hng\backend\stage-2\venv\Lib\site-packages\sqlalchemy\orm\session.py", line 1277, in _prepare_impl
    self.session.flush()
  File "C:\Users\USER\Documents\Projects\hng\backend\stage-2\venv\Lib\site-packages\sqlalchemy\orm\session.py", line 4341, in flush
    self._flush(objects)
  File "C:\Users\USER\Documents\Projects\hng\backend\stage-2\venv\Lib\site-packages\sqlalchemy\orm\session.py", line 4476, in _flush
    with util.safe_reraise():
  File "C:\Users\USER\Documents\Projects\hng\backend\stage-2\venv\Lib\site-packages\sqlalchemy\util\langhelpers.py", line 146, in __exit__
    raise exc_value.with_traceback(exc_tb)
  File "C:\Users\USER\Documents\Projects\hng\backend\stage-2\venv\Lib\site-packages\sqlalchemy\orm\session.py", line 4437, in _flush
    flush_context.execute()
  File "C:\Users\USER\Documents\Projects\hng\backend\stage-2\venv\Lib\site-packages\sqlalchemy\orm\unitofwork.py", line 466, in execute
    rec.execute(self)
  File "C:\Users\USER\Documents\Projects\hng\backend\stage-2\venv\Lib\site-packages\sqlalchemy\orm\unitofwork.py", line 642, in execute
    util.preloaded.orm_persistence.save_obj(
  File "C:\Users\USER\Documents\Projects\hng\backend\stage-2\venv\Lib\site-packages\sqlalchemy\orm\persistence.py", line 93, in save_obj
    _emit_insert_statements(
  File "C:\Users\USER\Documents\Projects\hng\backend\stage-2\venv\Lib\site-packages\sqlalchemy\orm\persistence.py", line 1233, in _emit_insert_statements
    result = connection.execute(
             ^^^^^^^^^^^^^^^^^^^
  File "C:\Users\USER\Documents\Projects\hng\backend\stage-2\venv\Lib\site-packages\sqlalchemy\engine\base.py", line 1418, in execute
    return meth(
           ^^^^^
  File "C:\Users\USER\Documents\Projects\hng\backend\stage-2\venv\Lib\site-packages\sqlalchemy\sql\elements.py", line 515, in _execute_on_connection
    return connection._execute_clauseelement(
           ^^^^^^^^^^^^^^^^^^^^^^^^^^^^^^^^^^
  File "C:\Users\USER\Documents\Projects\hng\backend\stage-2\venv\Lib\site-packages\sqlalchemy\engine\base.py", line 1640, in _execute_clauseelement
    ret = self._execute_context(
          ^^^^^^^^^^^^^^^^^^^^^^
  File "C:\Users\USER\Documents\Projects\hng\backend\stage-2\venv\Lib\site-packages\sqlalchemy\engine\base.py", line 1846, in _execute_context
    return self._exec_single_context(
           ^^^^^^^^^^^^^^^^^^^^^^^^^^
  File "C:\Users\USER\Documents\Projects\hng\backend\stage-2\venv\Lib\site-packages\sqlalchemy\engine\base.py", line 1986, in _exec_single_context
    self._handle_dbapi_exception(
  File "C:\Users\USER\Documents\Projects\hng\backend\stage-2\venv\Lib\site-packages\sqlalchemy\engine\base.py", line 2353, in _handle_dbapi_exception
    raise sqlalchemy_exception.with_traceback(exc_info[2]) from e
  File "C:\Users\USER\Documents\Projects\hng\backend\stage-2\venv\Lib\site-packages\sqlalchemy\engine\base.py", line 1967, in _exec_single_context
    self.dialect.do_execute(
  File "C:\Users\USER\Documents\Projects\hng\backend\stage-2\venv\Lib\site-packages\sqlalchemy\engine\default.py", line 924, in do_execute
    cursor.execute(statement, parameters)
sqlalchemy.exc.ProgrammingError: (psycopg2.errors.UndefinedTable) relation "user" does not exist
LINE 1: INSERT INTO "user" ("userId", "firstName", "lastName", email...
                    ^

[SQL: INSERT INTO "user" ("userId", "firstName", "lastName", email, password, phone) VALUES (%(userId)s, %(firstName)s, %(lastName)s, %(email)s, %(password)s, %(phone)s)]
[parameters: {'userId': '8603aea2-3127-43a6-88ca-2d6490562b0a', 'firstName': 'Emmanuel', 'lastName': 'Omoiys', 'email': 'emmanuelomoiya7@gmail.com', 'password': b'$2b$12$PKf6V7sFqKsmzBOv.nxpqe1nAVH65bGGngdtRRzBWPJxxDTiUCZoW', 'phone': '+2347043738436'}]
(Background on this error at: https://sqlalche.me/e/20/f405)
INFO:werkzeug:127.0.0.1 - - [09/Jul/2024 14:56:54] "[35m[1mPOST /auth/register HTTP/1.1[0m" 500 -
INFO:werkzeug:[31m[1mWARNING: This is a development server. Do not use it in a production deployment. Use a production WSGI server instead.[0m
 * Running on http://127.0.0.1:5000
INFO:werkzeug:[33mPress CTRL+C to quit[0m
INFO:werkzeug:127.0.0.1 - - [09/Jul/2024 15:17:27] "[35m[1mPOST /auth/register HTTP/1.1[0m" 201 -
ERROR:common.app:Exception on /auth/register [POST]
Traceback (most recent call last):
  File "C:\Users\USER\Documents\Projects\hng\backend\stage-2\venv\Lib\site-packages\sqlalchemy\engine\base.py", line 1967, in _exec_single_context
    self.dialect.do_execute(
  File "C:\Users\USER\Documents\Projects\hng\backend\stage-2\venv\Lib\site-packages\sqlalchemy\engine\default.py", line 924, in do_execute
    cursor.execute(statement, parameters)
psycopg2.errors.UniqueViolation: duplicate key value violates unique constraint "user_email_key"
DETAIL:  Key (email)=(emmanuelomoiya7@gmail.com) already exists.


The above exception was the direct cause of the following exception:

Traceback (most recent call last):
  File "C:\Users\USER\Documents\Projects\hng\backend\stage-2\venv\Lib\site-packages\flask\app.py", line 1473, in wsgi_app
    response = self.full_dispatch_request()
               ^^^^^^^^^^^^^^^^^^^^^^^^^^^^
  File "C:\Users\USER\Documents\Projects\hng\backend\stage-2\venv\Lib\site-packages\flask\app.py", line 882, in full_dispatch_request
    rv = self.handle_user_exception(e)
         ^^^^^^^^^^^^^^^^^^^^^^^^^^^^^
  File "C:\Users\USER\Documents\Projects\hng\backend\stage-2\venv\Lib\site-packages\flask_cors\extension.py", line 178, in wrapped_function
    return cors_after_request(app.make_response(f(*args, **kwargs)))
                                                ^^^^^^^^^^^^^^^^^^
  File "C:\Users\USER\Documents\Projects\hng\backend\stage-2\venv\Lib\site-packages\flask\app.py", line 880, in full_dispatch_request
    rv = self.dispatch_request()
         ^^^^^^^^^^^^^^^^^^^^^^^
  File "C:\Users\USER\Documents\Projects\hng\backend\stage-2\venv\Lib\site-packages\flask\app.py", line 865, in dispatch_request
    return self.ensure_sync(self.view_functions[rule.endpoint])(**view_args)  # type: ignore[no-any-return]
           ^^^^^^^^^^^^^^^^^^^^^^^^^^^^^^^^^^^^^^^^^^^^^^^^^^^^^^^^^^^^^^^^^
  File "C:\Users\USER\Documents\Projects\hng\backend\stage-2\routes\auth_route.py", line 14, in registerMain
    return register(data)
           ^^^^^^^^^^^^^^
  File "C:\Users\USER\Documents\Projects\hng\backend\stage-2\modules\auth\auth_controller.py", line 30, in register
    db.session.commit()
  File "C:\Users\USER\Documents\Projects\hng\backend\stage-2\venv\Lib\site-packages\sqlalchemy\orm\scoping.py", line 597, in commit
    return self._proxied.commit()
           ^^^^^^^^^^^^^^^^^^^^^^
  File "C:\Users\USER\Documents\Projects\hng\backend\stage-2\venv\Lib\site-packages\sqlalchemy\orm\session.py", line 2017, in commit
    trans.commit(_to_root=True)
  File "<string>", line 2, in commit
  File "C:\Users\USER\Documents\Projects\hng\backend\stage-2\venv\Lib\site-packages\sqlalchemy\orm\state_changes.py", line 139, in _go
    ret_value = fn(self, *arg, **kw)
                ^^^^^^^^^^^^^^^^^^^^
  File "C:\Users\USER\Documents\Projects\hng\backend\stage-2\venv\Lib\site-packages\sqlalchemy\orm\session.py", line 1302, in commit
    self._prepare_impl()
  File "<string>", line 2, in _prepare_impl
  File "C:\Users\USER\Documents\Projects\hng\backend\stage-2\venv\Lib\site-packages\sqlalchemy\orm\state_changes.py", line 139, in _go
    ret_value = fn(self, *arg, **kw)
                ^^^^^^^^^^^^^^^^^^^^
  File "C:\Users\USER\Documents\Projects\hng\backend\stage-2\venv\Lib\site-packages\sqlalchemy\orm\session.py", line 1277, in _prepare_impl
    self.session.flush()
  File "C:\Users\USER\Documents\Projects\hng\backend\stage-2\venv\Lib\site-packages\sqlalchemy\orm\session.py", line 4341, in flush
    self._flush(objects)
  File "C:\Users\USER\Documents\Projects\hng\backend\stage-2\venv\Lib\site-packages\sqlalchemy\orm\session.py", line 4476, in _flush
    with util.safe_reraise():
  File "C:\Users\USER\Documents\Projects\hng\backend\stage-2\venv\Lib\site-packages\sqlalchemy\util\langhelpers.py", line 146, in __exit__
    raise exc_value.with_traceback(exc_tb)
  File "C:\Users\USER\Documents\Projects\hng\backend\stage-2\venv\Lib\site-packages\sqlalchemy\orm\session.py", line 4437, in _flush
    flush_context.execute()
  File "C:\Users\USER\Documents\Projects\hng\backend\stage-2\venv\Lib\site-packages\sqlalchemy\orm\unitofwork.py", line 466, in execute
    rec.execute(self)
  File "C:\Users\USER\Documents\Projects\hng\backend\stage-2\venv\Lib\site-packages\sqlalchemy\orm\unitofwork.py", line 642, in execute
    util.preloaded.orm_persistence.save_obj(
  File "C:\Users\USER\Documents\Projects\hng\backend\stage-2\venv\Lib\site-packages\sqlalchemy\orm\persistence.py", line 93, in save_obj
    _emit_insert_statements(
  File "C:\Users\USER\Documents\Projects\hng\backend\stage-2\venv\Lib\site-packages\sqlalchemy\orm\persistence.py", line 1233, in _emit_insert_statements
    result = connection.execute(
             ^^^^^^^^^^^^^^^^^^^
  File "C:\Users\USER\Documents\Projects\hng\backend\stage-2\venv\Lib\site-packages\sqlalchemy\engine\base.py", line 1418, in execute
    return meth(
           ^^^^^
  File "C:\Users\USER\Documents\Projects\hng\backend\stage-2\venv\Lib\site-packages\sqlalchemy\sql\elements.py", line 515, in _execute_on_connection
    return connection._execute_clauseelement(
           ^^^^^^^^^^^^^^^^^^^^^^^^^^^^^^^^^^
  File "C:\Users\USER\Documents\Projects\hng\backend\stage-2\venv\Lib\site-packages\sqlalchemy\engine\base.py", line 1640, in _execute_clauseelement
    ret = self._execute_context(
          ^^^^^^^^^^^^^^^^^^^^^^
  File "C:\Users\USER\Documents\Projects\hng\backend\stage-2\venv\Lib\site-packages\sqlalchemy\engine\base.py", line 1846, in _execute_context
    return self._exec_single_context(
           ^^^^^^^^^^^^^^^^^^^^^^^^^^
  File "C:\Users\USER\Documents\Projects\hng\backend\stage-2\venv\Lib\site-packages\sqlalchemy\engine\base.py", line 1986, in _exec_single_context
    self._handle_dbapi_exception(
  File "C:\Users\USER\Documents\Projects\hng\backend\stage-2\venv\Lib\site-packages\sqlalchemy\engine\base.py", line 2353, in _handle_dbapi_exception
    raise sqlalchemy_exception.with_traceback(exc_info[2]) from e
  File "C:\Users\USER\Documents\Projects\hng\backend\stage-2\venv\Lib\site-packages\sqlalchemy\engine\base.py", line 1967, in _exec_single_context
    self.dialect.do_execute(
  File "C:\Users\USER\Documents\Projects\hng\backend\stage-2\venv\Lib\site-packages\sqlalchemy\engine\default.py", line 924, in do_execute
    cursor.execute(statement, parameters)
sqlalchemy.exc.IntegrityError: (psycopg2.errors.UniqueViolation) duplicate key value violates unique constraint "user_email_key"
DETAIL:  Key (email)=(emmanuelomoiya7@gmail.com) already exists.

[SQL: INSERT INTO "user" ("userId", "firstName", "lastName", email, password, phone) VALUES (%(userId)s, %(firstName)s, %(lastName)s, %(email)s, %(password)s, %(phone)s)]
[parameters: {'userId': '4f95c234-955a-463b-84d7-d09867e0f27c', 'firstName': 'Emmanuel', 'lastName': 'Omoiys', 'email': 'emmanuelomoiya7@gmail.com', 'password': b'$2b$12$4buMJUze.5Ba5vMGASUJfu39f3ui0FmJf3QiXFrmlkYiQ.gWXPqLa', 'phone': '+2347043738436'}]
(Background on this error at: https://sqlalche.me/e/20/gkpj)
INFO:werkzeug:127.0.0.1 - - [09/Jul/2024 15:17:40] "[35m[1mPOST /auth/register HTTP/1.1[0m" 500 -
ERROR:common.app:Exception on /auth/register [POST]
Traceback (most recent call last):
  File "C:\Users\USER\Documents\Projects\hng\backend\stage-2\venv\Lib\site-packages\sqlalchemy\engine\base.py", line 1967, in _exec_single_context
    self.dialect.do_execute(
  File "C:\Users\USER\Documents\Projects\hng\backend\stage-2\venv\Lib\site-packages\sqlalchemy\engine\default.py", line 924, in do_execute
    cursor.execute(statement, parameters)
psycopg2.errors.UniqueViolation: duplicate key value violates unique constraint "user_userId_key"
DETAIL:  Key ("userId")=(4f95c234-955a-463b-84d7-d09867e0f27c) already exists.


The above exception was the direct cause of the following exception:

Traceback (most recent call last):
  File "C:\Users\USER\Documents\Projects\hng\backend\stage-2\venv\Lib\site-packages\flask\app.py", line 1473, in wsgi_app
    response = self.full_dispatch_request()
               ^^^^^^^^^^^^^^^^^^^^^^^^^^^^
  File "C:\Users\USER\Documents\Projects\hng\backend\stage-2\venv\Lib\site-packages\flask\app.py", line 882, in full_dispatch_request
    rv = self.handle_user_exception(e)
         ^^^^^^^^^^^^^^^^^^^^^^^^^^^^^
  File "C:\Users\USER\Documents\Projects\hng\backend\stage-2\venv\Lib\site-packages\flask_cors\extension.py", line 178, in wrapped_function
    return cors_after_request(app.make_response(f(*args, **kwargs)))
                                                ^^^^^^^^^^^^^^^^^^
  File "C:\Users\USER\Documents\Projects\hng\backend\stage-2\venv\Lib\site-packages\flask\app.py", line 880, in full_dispatch_request
    rv = self.dispatch_request()
         ^^^^^^^^^^^^^^^^^^^^^^^
  File "C:\Users\USER\Documents\Projects\hng\backend\stage-2\venv\Lib\site-packages\flask\app.py", line 865, in dispatch_request
    return self.ensure_sync(self.view_functions[rule.endpoint])(**view_args)  # type: ignore[no-any-return]
           ^^^^^^^^^^^^^^^^^^^^^^^^^^^^^^^^^^^^^^^^^^^^^^^^^^^^^^^^^^^^^^^^^
  File "C:\Users\USER\Documents\Projects\hng\backend\stage-2\routes\auth_route.py", line 14, in registerMain
    return register(data)
           ^^^^^^^^^^^^^^
  File "C:\Users\USER\Documents\Projects\hng\backend\stage-2\modules\auth\auth_controller.py", line 30, in register
    password=hashed_password,
    ^^^^^^^^^^^^^^^^^^^
  File "C:\Users\USER\Documents\Projects\hng\backend\stage-2\venv\Lib\site-packages\sqlalchemy\orm\scoping.py", line 597, in commit
    return self._proxied.commit()
           ^^^^^^^^^^^^^^^^^^^^^^
  File "C:\Users\USER\Documents\Projects\hng\backend\stage-2\venv\Lib\site-packages\sqlalchemy\orm\session.py", line 2017, in commit
    trans.commit(_to_root=True)
  File "<string>", line 2, in commit
  File "C:\Users\USER\Documents\Projects\hng\backend\stage-2\venv\Lib\site-packages\sqlalchemy\orm\state_changes.py", line 139, in _go
    ret_value = fn(self, *arg, **kw)
                ^^^^^^^^^^^^^^^^^^^^
  File "C:\Users\USER\Documents\Projects\hng\backend\stage-2\venv\Lib\site-packages\sqlalchemy\orm\session.py", line 1302, in commit
    self._prepare_impl()
  File "<string>", line 2, in _prepare_impl
  File "C:\Users\USER\Documents\Projects\hng\backend\stage-2\venv\Lib\site-packages\sqlalchemy\orm\state_changes.py", line 139, in _go
    ret_value = fn(self, *arg, **kw)
                ^^^^^^^^^^^^^^^^^^^^
  File "C:\Users\USER\Documents\Projects\hng\backend\stage-2\venv\Lib\site-packages\sqlalchemy\orm\session.py", line 1277, in _prepare_impl
    self.session.flush()
  File "C:\Users\USER\Documents\Projects\hng\backend\stage-2\venv\Lib\site-packages\sqlalchemy\orm\session.py", line 4341, in flush
    self._flush(objects)
  File "C:\Users\USER\Documents\Projects\hng\backend\stage-2\venv\Lib\site-packages\sqlalchemy\orm\session.py", line 4476, in _flush
    with util.safe_reraise():
  File "C:\Users\USER\Documents\Projects\hng\backend\stage-2\venv\Lib\site-packages\sqlalchemy\util\langhelpers.py", line 146, in __exit__
    raise exc_value.with_traceback(exc_tb)
  File "C:\Users\USER\Documents\Projects\hng\backend\stage-2\venv\Lib\site-packages\sqlalchemy\orm\session.py", line 4437, in _flush
    flush_context.execute()
  File "C:\Users\USER\Documents\Projects\hng\backend\stage-2\venv\Lib\site-packages\sqlalchemy\orm\unitofwork.py", line 466, in execute
    rec.execute(self)
  File "C:\Users\USER\Documents\Projects\hng\backend\stage-2\venv\Lib\site-packages\sqlalchemy\orm\unitofwork.py", line 642, in execute
    util.preloaded.orm_persistence.save_obj(
  File "C:\Users\USER\Documents\Projects\hng\backend\stage-2\venv\Lib\site-packages\sqlalchemy\orm\persistence.py", line 93, in save_obj
    _emit_insert_statements(
  File "C:\Users\USER\Documents\Projects\hng\backend\stage-2\venv\Lib\site-packages\sqlalchemy\orm\persistence.py", line 1233, in _emit_insert_statements
    result = connection.execute(
             ^^^^^^^^^^^^^^^^^^^
  File "C:\Users\USER\Documents\Projects\hng\backend\stage-2\venv\Lib\site-packages\sqlalchemy\engine\base.py", line 1418, in execute
    return meth(
           ^^^^^
  File "C:\Users\USER\Documents\Projects\hng\backend\stage-2\venv\Lib\site-packages\sqlalchemy\sql\elements.py", line 515, in _execute_on_connection
    return connection._execute_clauseelement(
           ^^^^^^^^^^^^^^^^^^^^^^^^^^^^^^^^^^
  File "C:\Users\USER\Documents\Projects\hng\backend\stage-2\venv\Lib\site-packages\sqlalchemy\engine\base.py", line 1640, in _execute_clauseelement
    ret = self._execute_context(
          ^^^^^^^^^^^^^^^^^^^^^^
  File "C:\Users\USER\Documents\Projects\hng\backend\stage-2\venv\Lib\site-packages\sqlalchemy\engine\base.py", line 1846, in _execute_context
    return self._exec_single_context(
           ^^^^^^^^^^^^^^^^^^^^^^^^^^
  File "C:\Users\USER\Documents\Projects\hng\backend\stage-2\venv\Lib\site-packages\sqlalchemy\engine\base.py", line 1986, in _exec_single_context
    self._handle_dbapi_exception(
  File "C:\Users\USER\Documents\Projects\hng\backend\stage-2\venv\Lib\site-packages\sqlalchemy\engine\base.py", line 2353, in _handle_dbapi_exception
    raise sqlalchemy_exception.with_traceback(exc_info[2]) from e
  File "C:\Users\USER\Documents\Projects\hng\backend\stage-2\venv\Lib\site-packages\sqlalchemy\engine\base.py", line 1967, in _exec_single_context
    self.dialect.do_execute(
  File "C:\Users\USER\Documents\Projects\hng\backend\stage-2\venv\Lib\site-packages\sqlalchemy\engine\default.py", line 924, in do_execute
    cursor.execute(statement, parameters)
sqlalchemy.exc.IntegrityError: (psycopg2.errors.UniqueViolation) duplicate key value violates unique constraint "user_userId_key"
DETAIL:  Key ("userId")=(4f95c234-955a-463b-84d7-d09867e0f27c) already exists.

[SQL: INSERT INTO "user" ("userId", "firstName", "lastName", email, password, phone) VALUES (%(userId)s, %(firstName)s, %(lastName)s, %(email)s, %(password)s, %(phone)s)]
[parameters: {'userId': '4f95c234-955a-463b-84d7-d09867e0f27c', 'firstName': 'Emmanuel', 'lastName': 'Omoiya', 'email': 'emmanuelomoiya8@gmail.com', 'password': b'$2b$12$lbq8rhN5AGZ/j60sph9DaOqKPLId6flFu2FnsDxEPRWk0SgCFmWtW', 'phone': '+2347043738436'}]
(Background on this error at: https://sqlalche.me/e/20/gkpj)
INFO:werkzeug:127.0.0.1 - - [09/Jul/2024 15:26:10] "[35m[1mPOST /auth/register HTTP/1.1[0m" 500 -
INFO:werkzeug:[31m[1mWARNING: This is a development server. Do not use it in a production deployment. Use a production WSGI server instead.[0m
 * Running on http://127.0.0.1:5000
INFO:werkzeug:[33mPress CTRL+C to quit[0m
INFO:werkzeug:127.0.0.1 - - [09/Jul/2024 15:31:27] "[35m[1mPOST /auth/register HTTP/1.1[0m" 201 -
INFO:werkzeug:127.0.0.1 - - [09/Jul/2024 15:31:50] "[31m[1mPOST /auth/register HTTP/1.1[0m" 400 -
ERROR:common.app:Exception on /auth/register [POST]
Traceback (most recent call last):
  File "C:\Users\USER\Documents\Projects\hng\backend\stage-2\venv\Lib\site-packages\sqlalchemy\engine\base.py", line 1967, in _exec_single_context
    self.dialect.do_execute(
  File "C:\Users\USER\Documents\Projects\hng\backend\stage-2\venv\Lib\site-packages\sqlalchemy\engine\default.py", line 924, in do_execute
    cursor.execute(statement, parameters)
psycopg2.errors.UniqueViolation: duplicate key value violates unique constraint "organisation_orgId_key"
DETAIL:  Key ("orgId")=(56440dde-aacd-4f9f-b13c-a067a637bc9d) already exists.


The above exception was the direct cause of the following exception:

Traceback (most recent call last):
  File "C:\Users\USER\Documents\Projects\hng\backend\stage-2\venv\Lib\site-packages\flask\app.py", line 1473, in wsgi_app
    response = self.full_dispatch_request()
               ^^^^^^^^^^^^^^^^^^^^^^^^^^^^
  File "C:\Users\USER\Documents\Projects\hng\backend\stage-2\venv\Lib\site-packages\flask\app.py", line 882, in full_dispatch_request
    rv = self.handle_user_exception(e)
         ^^^^^^^^^^^^^^^^^^^^^^^^^^^^^
  File "C:\Users\USER\Documents\Projects\hng\backend\stage-2\venv\Lib\site-packages\flask_cors\extension.py", line 178, in wrapped_function
    return cors_after_request(app.make_response(f(*args, **kwargs)))
                                                ^^^^^^^^^^^^^^^^^^
  File "C:\Users\USER\Documents\Projects\hng\backend\stage-2\venv\Lib\site-packages\flask\app.py", line 880, in full_dispatch_request
    rv = self.dispatch_request()
         ^^^^^^^^^^^^^^^^^^^^^^^
  File "C:\Users\USER\Documents\Projects\hng\backend\stage-2\venv\Lib\site-packages\flask\app.py", line 865, in dispatch_request
    return self.ensure_sync(self.view_functions[rule.endpoint])(**view_args)  # type: ignore[no-any-return]
           ^^^^^^^^^^^^^^^^^^^^^^^^^^^^^^^^^^^^^^^^^^^^^^^^^^^^^^^^^^^^^^^^^
  File "C:\Users\USER\Documents\Projects\hng\backend\stage-2\routes\auth_route.py", line 14, in registerMain
    return register(data)
           ^^^^^^^^^^^^^^
  File "C:\Users\USER\Documents\Projects\hng\backend\stage-2\modules\auth\auth_controller.py", line 40, in register
    db.session.commit()
  File "C:\Users\USER\Documents\Projects\hng\backend\stage-2\venv\Lib\site-packages\sqlalchemy\orm\scoping.py", line 597, in commit
    return self._proxied.commit()
           ^^^^^^^^^^^^^^^^^^^^^^
  File "C:\Users\USER\Documents\Projects\hng\backend\stage-2\venv\Lib\site-packages\sqlalchemy\orm\session.py", line 2017, in commit
    trans.commit(_to_root=True)
  File "<string>", line 2, in commit
  File "C:\Users\USER\Documents\Projects\hng\backend\stage-2\venv\Lib\site-packages\sqlalchemy\orm\state_changes.py", line 139, in _go
    ret_value = fn(self, *arg, **kw)
                ^^^^^^^^^^^^^^^^^^^^
  File "C:\Users\USER\Documents\Projects\hng\backend\stage-2\venv\Lib\site-packages\sqlalchemy\orm\session.py", line 1302, in commit
    self._prepare_impl()
  File "<string>", line 2, in _prepare_impl
  File "C:\Users\USER\Documents\Projects\hng\backend\stage-2\venv\Lib\site-packages\sqlalchemy\orm\state_changes.py", line 139, in _go
    ret_value = fn(self, *arg, **kw)
                ^^^^^^^^^^^^^^^^^^^^
  File "C:\Users\USER\Documents\Projects\hng\backend\stage-2\venv\Lib\site-packages\sqlalchemy\orm\session.py", line 1277, in _prepare_impl
    self.session.flush()
  File "C:\Users\USER\Documents\Projects\hng\backend\stage-2\venv\Lib\site-packages\sqlalchemy\orm\session.py", line 4341, in flush
    self._flush(objects)
  File "C:\Users\USER\Documents\Projects\hng\backend\stage-2\venv\Lib\site-packages\sqlalchemy\orm\session.py", line 4476, in _flush
    with util.safe_reraise():
  File "C:\Users\USER\Documents\Projects\hng\backend\stage-2\venv\Lib\site-packages\sqlalchemy\util\langhelpers.py", line 146, in __exit__
    raise exc_value.with_traceback(exc_tb)
  File "C:\Users\USER\Documents\Projects\hng\backend\stage-2\venv\Lib\site-packages\sqlalchemy\orm\session.py", line 4437, in _flush
    flush_context.execute()
  File "C:\Users\USER\Documents\Projects\hng\backend\stage-2\venv\Lib\site-packages\sqlalchemy\orm\unitofwork.py", line 466, in execute
    rec.execute(self)
  File "C:\Users\USER\Documents\Projects\hng\backend\stage-2\venv\Lib\site-packages\sqlalchemy\orm\unitofwork.py", line 642, in execute
    util.preloaded.orm_persistence.save_obj(
  File "C:\Users\USER\Documents\Projects\hng\backend\stage-2\venv\Lib\site-packages\sqlalchemy\orm\persistence.py", line 93, in save_obj
    _emit_insert_statements(
  File "C:\Users\USER\Documents\Projects\hng\backend\stage-2\venv\Lib\site-packages\sqlalchemy\orm\persistence.py", line 1233, in _emit_insert_statements
    result = connection.execute(
             ^^^^^^^^^^^^^^^^^^^
  File "C:\Users\USER\Documents\Projects\hng\backend\stage-2\venv\Lib\site-packages\sqlalchemy\engine\base.py", line 1418, in execute
    return meth(
           ^^^^^
  File "C:\Users\USER\Documents\Projects\hng\backend\stage-2\venv\Lib\site-packages\sqlalchemy\sql\elements.py", line 515, in _execute_on_connection
    return connection._execute_clauseelement(
           ^^^^^^^^^^^^^^^^^^^^^^^^^^^^^^^^^^
  File "C:\Users\USER\Documents\Projects\hng\backend\stage-2\venv\Lib\site-packages\sqlalchemy\engine\base.py", line 1640, in _execute_clauseelement
    ret = self._execute_context(
          ^^^^^^^^^^^^^^^^^^^^^^
  File "C:\Users\USER\Documents\Projects\hng\backend\stage-2\venv\Lib\site-packages\sqlalchemy\engine\base.py", line 1846, in _execute_context
    return self._exec_single_context(
           ^^^^^^^^^^^^^^^^^^^^^^^^^^
  File "C:\Users\USER\Documents\Projects\hng\backend\stage-2\venv\Lib\site-packages\sqlalchemy\engine\base.py", line 1986, in _exec_single_context
    self._handle_dbapi_exception(
  File "C:\Users\USER\Documents\Projects\hng\backend\stage-2\venv\Lib\site-packages\sqlalchemy\engine\base.py", line 2353, in _handle_dbapi_exception
    raise sqlalchemy_exception.with_traceback(exc_info[2]) from e
  File "C:\Users\USER\Documents\Projects\hng\backend\stage-2\venv\Lib\site-packages\sqlalchemy\engine\base.py", line 1967, in _exec_single_context
    self.dialect.do_execute(
  File "C:\Users\USER\Documents\Projects\hng\backend\stage-2\venv\Lib\site-packages\sqlalchemy\engine\default.py", line 924, in do_execute
    cursor.execute(statement, parameters)
sqlalchemy.exc.IntegrityError: (psycopg2.errors.UniqueViolation) duplicate key value violates unique constraint "organisation_orgId_key"
DETAIL:  Key ("orgId")=(56440dde-aacd-4f9f-b13c-a067a637bc9d) already exists.

[SQL: INSERT INTO organisation ("orgId", name, description, creator_id) VALUES (%(orgId)s, %(name)s, %(description)s, %(creator_id)s)]
[parameters: {'orgId': '56440dde-aacd-4f9f-b13c-a067a637bc9d', 'name': "Emmanuel's Organisation", 'description': None, 'creator_id': '388befc1-1572-401a-a7ab-288835925f83'}]
(Background on this error at: https://sqlalche.me/e/20/gkpj)
INFO:werkzeug:127.0.0.1 - - [09/Jul/2024 15:32:04] "[35m[1mPOST /auth/register HTTP/1.1[0m" 500 -
INFO:werkzeug:127.0.0.1 - - [09/Jul/2024 15:33:52] "[31m[1mPOST /auth/register HTTP/1.1[0m" 400 -
ERROR:common.app:Exception on /auth/register [POST]
Traceback (most recent call last):
  File "C:\Users\USER\Documents\Projects\hng\backend\stage-2\venv\Lib\site-packages\sqlalchemy\engine\base.py", line 1967, in _exec_single_context
    self.dialect.do_execute(
  File "C:\Users\USER\Documents\Projects\hng\backend\stage-2\venv\Lib\site-packages\sqlalchemy\engine\default.py", line 924, in do_execute
    cursor.execute(statement, parameters)
psycopg2.errors.UniqueViolation: duplicate key value violates unique constraint "organisation_orgId_key"
DETAIL:  Key ("orgId")=(56440dde-aacd-4f9f-b13c-a067a637bc9d) already exists.


The above exception was the direct cause of the following exception:

Traceback (most recent call last):
  File "C:\Users\USER\Documents\Projects\hng\backend\stage-2\venv\Lib\site-packages\flask\app.py", line 1473, in wsgi_app
    response = self.full_dispatch_request()
               ^^^^^^^^^^^^^^^^^^^^^^^^^^^^
  File "C:\Users\USER\Documents\Projects\hng\backend\stage-2\venv\Lib\site-packages\flask\app.py", line 882, in full_dispatch_request
    rv = self.handle_user_exception(e)
         ^^^^^^^^^^^^^^^^^^^^^^^^^^^^^
  File "C:\Users\USER\Documents\Projects\hng\backend\stage-2\venv\Lib\site-packages\flask_cors\extension.py", line 178, in wrapped_function
    return cors_after_request(app.make_response(f(*args, **kwargs)))
                                                ^^^^^^^^^^^^^^^^^^
  File "C:\Users\USER\Documents\Projects\hng\backend\stage-2\venv\Lib\site-packages\flask\app.py", line 880, in full_dispatch_request
    rv = self.dispatch_request()
         ^^^^^^^^^^^^^^^^^^^^^^^
  File "C:\Users\USER\Documents\Projects\hng\backend\stage-2\venv\Lib\site-packages\flask\app.py", line 865, in dispatch_request
    return self.ensure_sync(self.view_functions[rule.endpoint])(**view_args)  # type: ignore[no-any-return]
           ^^^^^^^^^^^^^^^^^^^^^^^^^^^^^^^^^^^^^^^^^^^^^^^^^^^^^^^^^^^^^^^^^
  File "C:\Users\USER\Documents\Projects\hng\backend\stage-2\routes\auth_route.py", line 14, in registerMain
    return register(data)
           ^^^^^^^^^^^^^^
  File "C:\Users\USER\Documents\Projects\hng\backend\stage-2\modules\auth\auth_controller.py", line 40, in register
    db.session.commit()
  File "C:\Users\USER\Documents\Projects\hng\backend\stage-2\venv\Lib\site-packages\sqlalchemy\orm\scoping.py", line 597, in commit
    return self._proxied.commit()
           ^^^^^^^^^^^^^^^^^^^^^^
  File "C:\Users\USER\Documents\Projects\hng\backend\stage-2\venv\Lib\site-packages\sqlalchemy\orm\session.py", line 2017, in commit
    trans.commit(_to_root=True)
  File "<string>", line 2, in commit
  File "C:\Users\USER\Documents\Projects\hng\backend\stage-2\venv\Lib\site-packages\sqlalchemy\orm\state_changes.py", line 139, in _go
    ret_value = fn(self, *arg, **kw)
                ^^^^^^^^^^^^^^^^^^^^
  File "C:\Users\USER\Documents\Projects\hng\backend\stage-2\venv\Lib\site-packages\sqlalchemy\orm\session.py", line 1302, in commit
    self._prepare_impl()
  File "<string>", line 2, in _prepare_impl
  File "C:\Users\USER\Documents\Projects\hng\backend\stage-2\venv\Lib\site-packages\sqlalchemy\orm\state_changes.py", line 139, in _go
    ret_value = fn(self, *arg, **kw)
                ^^^^^^^^^^^^^^^^^^^^
  File "C:\Users\USER\Documents\Projects\hng\backend\stage-2\venv\Lib\site-packages\sqlalchemy\orm\session.py", line 1277, in _prepare_impl
    self.session.flush()
  File "C:\Users\USER\Documents\Projects\hng\backend\stage-2\venv\Lib\site-packages\sqlalchemy\orm\session.py", line 4341, in flush
    self._flush(objects)
  File "C:\Users\USER\Documents\Projects\hng\backend\stage-2\venv\Lib\site-packages\sqlalchemy\orm\session.py", line 4476, in _flush
    with util.safe_reraise():
  File "C:\Users\USER\Documents\Projects\hng\backend\stage-2\venv\Lib\site-packages\sqlalchemy\util\langhelpers.py", line 146, in __exit__
    raise exc_value.with_traceback(exc_tb)
  File "C:\Users\USER\Documents\Projects\hng\backend\stage-2\venv\Lib\site-packages\sqlalchemy\orm\session.py", line 4437, in _flush
    flush_context.execute()
  File "C:\Users\USER\Documents\Projects\hng\backend\stage-2\venv\Lib\site-packages\sqlalchemy\orm\unitofwork.py", line 466, in execute
    rec.execute(self)
  File "C:\Users\USER\Documents\Projects\hng\backend\stage-2\venv\Lib\site-packages\sqlalchemy\orm\unitofwork.py", line 642, in execute
    util.preloaded.orm_persistence.save_obj(
  File "C:\Users\USER\Documents\Projects\hng\backend\stage-2\venv\Lib\site-packages\sqlalchemy\orm\persistence.py", line 93, in save_obj
    _emit_insert_statements(
  File "C:\Users\USER\Documents\Projects\hng\backend\stage-2\venv\Lib\site-packages\sqlalchemy\orm\persistence.py", line 1233, in _emit_insert_statements
    result = connection.execute(
             ^^^^^^^^^^^^^^^^^^^
  File "C:\Users\USER\Documents\Projects\hng\backend\stage-2\venv\Lib\site-packages\sqlalchemy\engine\base.py", line 1418, in execute
    return meth(
           ^^^^^
  File "C:\Users\USER\Documents\Projects\hng\backend\stage-2\venv\Lib\site-packages\sqlalchemy\sql\elements.py", line 515, in _execute_on_connection
    return connection._execute_clauseelement(
           ^^^^^^^^^^^^^^^^^^^^^^^^^^^^^^^^^^
  File "C:\Users\USER\Documents\Projects\hng\backend\stage-2\venv\Lib\site-packages\sqlalchemy\engine\base.py", line 1640, in _execute_clauseelement
    ret = self._execute_context(
          ^^^^^^^^^^^^^^^^^^^^^^
  File "C:\Users\USER\Documents\Projects\hng\backend\stage-2\venv\Lib\site-packages\sqlalchemy\engine\base.py", line 1846, in _execute_context
    return self._exec_single_context(
           ^^^^^^^^^^^^^^^^^^^^^^^^^^
  File "C:\Users\USER\Documents\Projects\hng\backend\stage-2\venv\Lib\site-packages\sqlalchemy\engine\base.py", line 1986, in _exec_single_context
    self._handle_dbapi_exception(
  File "C:\Users\USER\Documents\Projects\hng\backend\stage-2\venv\Lib\site-packages\sqlalchemy\engine\base.py", line 2353, in _handle_dbapi_exception
    raise sqlalchemy_exception.with_traceback(exc_info[2]) from e
  File "C:\Users\USER\Documents\Projects\hng\backend\stage-2\venv\Lib\site-packages\sqlalchemy\engine\base.py", line 1967, in _exec_single_context
    self.dialect.do_execute(
  File "C:\Users\USER\Documents\Projects\hng\backend\stage-2\venv\Lib\site-packages\sqlalchemy\engine\default.py", line 924, in do_execute
    cursor.execute(statement, parameters)
sqlalchemy.exc.IntegrityError: (psycopg2.errors.UniqueViolation) duplicate key value violates unique constraint "organisation_orgId_key"
DETAIL:  Key ("orgId")=(56440dde-aacd-4f9f-b13c-a067a637bc9d) already exists.

[SQL: INSERT INTO organisation ("orgId", name, description, creator_id) VALUES (%(orgId)s, %(name)s, %(description)s, %(creator_id)s)]
[parameters: {'orgId': '56440dde-aacd-4f9f-b13c-a067a637bc9d', 'name': "Emmanuel's Organisation", 'description': None, 'creator_id': '17ada18b-0adc-4ff1-a404-e1b4fe405357'}]
(Background on this error at: https://sqlalche.me/e/20/gkpj)
INFO:werkzeug:127.0.0.1 - - [09/Jul/2024 15:34:00] "[35m[1mPOST /auth/register HTTP/1.1[0m" 500 -
INFO:werkzeug:[31m[1mWARNING: This is a development server. Do not use it in a production deployment. Use a production WSGI server instead.[0m
 * Running on http://127.0.0.1:5000
INFO:werkzeug:[33mPress CTRL+C to quit[0m
INFO:werkzeug:127.0.0.1 - - [09/Jul/2024 15:34:37] "[35m[1mPOST /auth/register HTTP/1.1[0m" 201 -
INFO:werkzeug:127.0.0.1 - - [09/Jul/2024 15:34:44] "[35m[1mPOST /auth/register HTTP/1.1[0m" 201 -
